<robot name = "robot">
    <link name="0">
        <inertial>
            <origin xyz="0 0 0.75" rpy="0 0 0"/>
            <mass value="1" />
            <inertia ixx="100" ixy="0" ixz="0" iyy="100" iyz="0" izz="100" />
        </inertial>
        <visual>
            <origin xyz="0 0 0.75" rpy="0 0 0"/>
            <geometry>
                <box size="0.5019236759933152 1.2619169612797685 0.17773786424552596" />
            </geometry>
            <material name="Blue">
                <color rgba="0 0 1 1.0"/>
            </material>
        </visual>
        <collision>
            <origin xyz="0 0 0.75" rpy="0 0 0"/>
            <geometry>
                <box size="0.5019236759933152 1.2619169612797685 0.17773786424552596" />
            </geometry>
        </collision>
    </link>
    <joint name="0_1addl" type="revolute">
       <parent link="0"/>
       <child  link="1addl"/>
       <origin rpy="0 0 0" xyz="0 0 0.8388689321227629" />
     <axis xyz="0 0 1"/>
       <limit effort="0.0" lower="-3.14159" upper="3.14159" velocity="0.0"/>
    </joint>
    <link name="1addl">
        <inertial>
            <origin xyz="0 0 0.44801470497991225" rpy="0 0 0"/>
            <mass value="1" />
            <inertia ixx="100" ixy="0" ixz="0" iyy="100" iyz="0" izz="100" />
        </inertial>
        <visual>
            <origin xyz="0 0 0.44801470497991225" rpy="0 0 0"/>
            <geometry>
                <box size="0.47002617665873325 0.6505937778923739 0.8960294099598245" />
            </geometry>
            <material name="Blue">
                <color rgba="0 0 1 1.0"/>
            </material>
        </visual>
        <collision>
            <origin xyz="0 0 0.44801470497991225" rpy="0 0 0"/>
            <geometry>
                <box size="0.47002617665873325 0.6505937778923739 0.8960294099598245" />
            </geometry>
        </collision>
    </link>
    <joint name="0_1" type="revolute">
       <parent link="0"/>
       <child  link="1"/>
       <origin rpy="0 0 0" xyz="0 0.6309584806398842 0.75" />
     <axis xyz="0 0 1"/>
       <limit effort="0.0" lower="-3.14159" upper="3.14159" velocity="0.0"/>
    </joint>
    <link name="1">
        <inertial>
            <origin xyz="0 0.9699261818163564 0" rpy="0 0 0"/>
            <mass value="1" />
            <inertia ixx="100" ixy="0" ixz="0" iyy="100" iyz="0" izz="100" />
        </inertial>
        <visual>
            <origin xyz="0 0.9699261818163564 0" rpy="0 0 0"/>
            <geometry>
                <box size="1.0268058515751508 1.9398523636327127 0.21925040334879206" />
            </geometry>
            <material name="Blue">
                <color rgba="0 0 1 1.0"/>
            </material>
        </visual>
        <collision>
            <origin xyz="0 0.9699261818163564 0" rpy="0 0 0"/>
            <geometry>
                <box size="1.0268058515751508 1.9398523636327127 0.21925040334879206" />
            </geometry>
        </collision>
    </link>
    <joint name="1_2" type="revolute">
       <parent link="1"/>
       <child  link="2"/>
       <origin rpy="0 0 0" xyz="0 1.9398523636327127 0" />
     <axis xyz="1 0 0"/>
       <limit effort="0.0" lower="-3.14159" upper="3.14159" velocity="0.0"/>
    </joint>
    <link name="2">
        <inertial>
            <origin xyz="0 0.9530459947952756 0" rpy="0 0 0"/>
            <mass value="1" />
            <inertia ixx="100" ixy="0" ixz="0" iyy="100" iyz="0" izz="100" />
        </inertial>
        <visual>
            <origin xyz="0 0.9530459947952756 0" rpy="0 0 0"/>
            <geometry>
                <box size="0.14757957599372487 1.9060919895905513 0.1939696599875003" />
            </geometry>
            <material name="Green">
                <color rgba="0 1 0 1.0"/>
            </material>
        </visual>
        <collision>
            <origin xyz="0 0.9530459947952756 0" rpy="0 0 0"/>
            <geometry>
                <box size="0.14757957599372487 1.9060919895905513 0.1939696599875003" />
            </geometry>
        </collision>
    </link>
    <joint name="2_3" type="revolute">
       <parent link="2"/>
       <child  link="3"/>
       <origin rpy="0 0 0" xyz="0 0.9530459947952756 0.09698482999375015" />
     <axis xyz="1 0 0"/>
       <limit effort="0.0" lower="-3.14159" upper="3.14159" velocity="0.0"/>
    </joint>
    <link name="3">
        <inertial>
            <origin xyz="0 0 0.6813704037592283" rpy="0 0 0"/>
            <mass value="1" />
            <inertia ixx="100" ixy="0" ixz="0" iyy="100" iyz="0" izz="100" />
        </inertial>
        <visual>
            <origin xyz="0 0 0.6813704037592283" rpy="0 0 0"/>
            <geometry>
                <box size="0.4630426927391266 0.7264917496570236 1.3627408075184566" />
            </geometry>
            <material name="Green">
                <color rgba="0 1 0 1.0"/>
            </material>
        </visual>
        <collision>
            <origin xyz="0 0 0.6813704037592283" rpy="0 0 0"/>
            <geometry>
                <box size="0.4630426927391266 0.7264917496570236 1.3627408075184566" />
            </geometry>
        </collision>
    </link>
</robot>