<robot name = "robot">
    <link name="0">
        <inertial>
            <origin xyz="0 0 0.75" rpy="0 0 0"/>
            <mass value="1" />
            <inertia ixx="100" ixy="0" ixz="0" iyy="100" iyz="0" izz="100" />
        </inertial>
        <visual>
            <origin xyz="0 0 0.75" rpy="0 0 0"/>
            <geometry>
                <box size="1.140405324591497 1.3538055524980883 1.4625531598602866" />
            </geometry>
            <material name="Green">
                <color rgba="0 1 0 1.0"/>
            </material>
        </visual>
        <collision>
            <origin xyz="0 0 0.75" rpy="0 0 0"/>
            <geometry>
                <box size="1.140405324591497 1.3538055524980883 1.4625531598602866" />
            </geometry>
        </collision>
    </link>
    <joint name="0_1" type="revolute">
       <parent link="0"/>
       <child  link="1"/>
       <origin rpy="0 0 0" xyz="0 0 1.4812765799301433" />
     <axis xyz="1 0 0"/>
       <limit effort="0.0" lower="-3.14159" upper="3.14159" velocity="0.0"/>
    </joint>
    <link name="1">
        <inertial>
            <origin xyz="0 0 0.9226128486009831" rpy="0 0 0"/>
            <mass value="1" />
            <inertia ixx="100" ixy="0" ixz="0" iyy="100" iyz="0" izz="100" />
        </inertial>
        <visual>
            <origin xyz="0 0 0.9226128486009831" rpy="0 0 0"/>
            <geometry>
                <box size="1.0384277929796994 0.5247159153060846 1.8452256972019663" />
            </geometry>
            <material name="Green">
                <color rgba="0 1 0 1.0"/>
            </material>
        </visual>
        <collision>
            <origin xyz="0 0 0.9226128486009831" rpy="0 0 0"/>
            <geometry>
                <box size="1.0384277929796994 0.5247159153060846 1.8452256972019663" />
            </geometry>
        </collision>
    </link>
    <joint name="1_2" type="revolute">
       <parent link="1"/>
       <child  link="2"/>
       <origin rpy="0 0 0" xyz="0 0.2623579576530423 0.9226128486009831" />
     <axis xyz="0 0 1"/>
       <limit effort="0.0" lower="-3.14159" upper="3.14159" velocity="0.0"/>
    </joint>
    <link name="2">
        <inertial>
            <origin xyz="0 0.30243734302133773 0" rpy="0 0 0"/>
            <mass value="1" />
            <inertia ixx="100" ixy="0" ixz="0" iyy="100" iyz="0" izz="100" />
        </inertial>
        <visual>
            <origin xyz="0 0.30243734302133773 0" rpy="0 0 0"/>
            <geometry>
                <box size="0.15160138456876152 0.6048746860426755 0.9110859843729464" />
            </geometry>
            <material name="Green">
                <color rgba="0 1 0 1.0"/>
            </material>
        </visual>
        <collision>
            <origin xyz="0 0.30243734302133773 0" rpy="0 0 0"/>
            <geometry>
                <box size="0.15160138456876152 0.6048746860426755 0.9110859843729464" />
            </geometry>
        </collision>
    </link>
</robot>