<robot name = "robot">
    <link name="0">
        <inertial>
            <origin xyz="0 0 0.75" rpy="0 0 0"/>
            <mass value="1" />
            <inertia ixx="100" ixy="0" ixz="0" iyy="100" iyz="0" izz="100" />
        </inertial>
        <visual>
            <origin xyz="0 0 0.75" rpy="0 0 0"/>
            <geometry>
                <box size="0.7205477510084143 0.9575390380822445 0.8077743831917102" />
            </geometry>
            <material name="Blue">
                <color rgba="0 0 1 1.0"/>
            </material>
        </visual>
        <collision>
            <origin xyz="0 0 0.75" rpy="0 0 0"/>
            <geometry>
                <box size="0.7205477510084143 0.9575390380822445 0.8077743831917102" />
            </geometry>
        </collision>
    </link>
    <joint name="0_1addl" type="revolute">
       <parent link="0"/>
       <child  link="1addl"/>
       <origin rpy="0 0 0" xyz="0 0.47876951904112225 0.75" />
     <axis xyz="0 0 1"/>
       <limit effort="0.0" lower="-3.14159" upper="3.14159" velocity="0.0"/>
    </joint>
    <link name="1addl">
        <inertial>
            <origin xyz="0 0.28232967448234414 0" rpy="0 0 0"/>
            <mass value="1" />
            <inertia ixx="100" ixy="0" ixz="0" iyy="100" iyz="0" izz="100" />
        </inertial>
        <visual>
            <origin xyz="0 0.28232967448234414 0" rpy="0 0 0"/>
            <geometry>
                <box size="0.9034794475804294 0.5646593489646883 0.5027753995613827" />
            </geometry>
            <material name="Green">
                <color rgba="0 1 0 1.0"/>
            </material>
        </visual>
        <collision>
            <origin xyz="0 0.28232967448234414 0" rpy="0 0 0"/>
            <geometry>
                <box size="0.9034794475804294 0.5646593489646883 0.5027753995613827" />
            </geometry>
        </collision>
    </link>
    <joint name="0_1" type="revolute">
       <parent link="0"/>
       <child  link="1"/>
       <origin rpy="0 0 0" xyz="0 0 1.153887191595855" />
     <axis xyz="1 0 0"/>
       <limit effort="0.0" lower="-3.14159" upper="3.14159" velocity="0.0"/>
    </joint>
    <link name="1">
        <inertial>
            <origin xyz="0 0 0.4420969731583648" rpy="0 0 0"/>
            <mass value="1" />
            <inertia ixx="100" ixy="0" ixz="0" iyy="100" iyz="0" izz="100" />
        </inertial>
        <visual>
            <origin xyz="0 0 0.4420969731583648" rpy="0 0 0"/>
            <geometry>
                <box size="0.8223909402079179 0.25659873229124386 0.8841939463167297" />
            </geometry>
            <material name="Green">
                <color rgba="0 1 0 1.0"/>
            </material>
        </visual>
        <collision>
            <origin xyz="0 0 0.4420969731583648" rpy="0 0 0"/>
            <geometry>
                <box size="0.8223909402079179 0.25659873229124386 0.8841939463167297" />
            </geometry>
        </collision>
    </link>
    <joint name="1_2addl" type="revolute">
       <parent link="1"/>
       <child  link="2addl"/>
       <origin rpy="0 0 0" xyz="0.41119547010395896 0 0.4420969731583648" />
     <axis xyz="0 1 0"/>
       <limit effort="0.0" lower="-3.14159" upper="3.14159" velocity="0.0"/>
    </joint>
    <link name="2addl">
        <inertial>
            <origin xyz="0.8942971445131269 0 0" rpy="0 0 0"/>
            <mass value="1" />
            <inertia ixx="100" ixy="0" ixz="0" iyy="100" iyz="0" izz="100" />
        </inertial>
        <visual>
            <origin xyz="0.8942971445131269 0 0" rpy="0 0 0"/>
            <geometry>
                <box size="1.7885942890262538 0.31020019473300026 0.45601072793639125" />
            </geometry>
            <material name="Green">
                <color rgba="0 1 0 1.0"/>
            </material>
        </visual>
        <collision>
            <origin xyz="0.8942971445131269 0 0" rpy="0 0 0"/>
            <geometry>
                <box size="1.7885942890262538 0.31020019473300026 0.45601072793639125" />
            </geometry>
        </collision>
    </link>
    <joint name="1_2" type="revolute">
       <parent link="1"/>
       <child  link="2"/>
       <origin rpy="0 0 0" xyz="0 0.12829936614562193 0.4420969731583648" />
     <axis xyz="0 0 1"/>
       <limit effort="0.0" lower="-3.14159" upper="3.14159" velocity="0.0"/>
    </joint>
    <link name="2">
        <inertial>
            <origin xyz="0 0.6326711871306581 0" rpy="0 0 0"/>
            <mass value="1" />
            <inertia ixx="100" ixy="0" ixz="0" iyy="100" iyz="0" izz="100" />
        </inertial>
        <visual>
            <origin xyz="0 0.6326711871306581 0" rpy="0 0 0"/>
            <geometry>
                <box size="1.0398481363124277 1.2653423742613161 0.5835114715114134" />
            </geometry>
            <material name="Green">
                <color rgba="0 1 0 1.0"/>
            </material>
        </visual>
        <collision>
            <origin xyz="0 0.6326711871306581 0" rpy="0 0 0"/>
            <geometry>
                <box size="1.0398481363124277 1.2653423742613161 0.5835114715114134" />
            </geometry>
        </collision>
    </link>
    <joint name="2_3" type="revolute">
       <parent link="2"/>
       <child  link="3"/>
       <origin rpy="0 0 0" xyz="0 1.2653423742613161 0" />
     <axis xyz="0 1 0"/>
       <limit effort="0.0" lower="-3.14159" upper="3.14159" velocity="0.0"/>
    </joint>
    <link name="3">
        <inertial>
            <origin xyz="0 0.4311300916102872 0" rpy="0 0 0"/>
            <mass value="1" />
            <inertia ixx="100" ixy="0" ixz="0" iyy="100" iyz="0" izz="100" />
        </inertial>
        <visual>
            <origin xyz="0 0.4311300916102872 0" rpy="0 0 0"/>
            <geometry>
                <box size="0.9207418627701496 0.8622601832205744 1.1357188247870844" />
            </geometry>
            <material name="Green">
                <color rgba="0 1 0 1.0"/>
            </material>
        </visual>
        <collision>
            <origin xyz="0 0.4311300916102872 0" rpy="0 0 0"/>
            <geometry>
                <box size="0.9207418627701496 0.8622601832205744 1.1357188247870844" />
            </geometry>
        </collision>
    </link>
</robot>