<robot name = "robot">
    <link name="0">
        <inertial>
            <origin xyz="0 0 0.75" rpy="0 0 0"/>
            <mass value="1" />
            <inertia ixx="100" ixy="0" ixz="0" iyy="100" iyz="0" izz="100" />
        </inertial>
        <visual>
            <origin xyz="0 0 0.75" rpy="0 0 0"/>
            <geometry>
                <box size="0.2635984121769591 0.8975926083635306 1.4478573043743745" />
            </geometry>
            <material name="Blue">
                <color rgba="0 0 1 1.0"/>
            </material>
        </visual>
        <collision>
            <origin xyz="0 0 0.75" rpy="0 0 0"/>
            <geometry>
                <box size="0.2635984121769591 0.8975926083635306 1.4478573043743745" />
            </geometry>
        </collision>
    </link>
    <joint name="0_1addl" type="revolute">
       <parent link="0"/>
       <child  link="1addl"/>
       <origin rpy="0 0 0" xyz="0 0 1.4739286521871873" />
     <axis xyz="0 1 0"/>
       <limit effort="0.0" lower="-3.14159" upper="3.14159" velocity="0.0"/>
    </joint>
    <link name="1addl">
        <inertial>
            <origin xyz="0 0 0.910627767281566" rpy="0 0 0"/>
            <mass value="1" />
            <inertia ixx="100" ixy="0" ixz="0" iyy="100" iyz="0" izz="100" />
        </inertial>
        <visual>
            <origin xyz="0 0 0.910627767281566" rpy="0 0 0"/>
            <geometry>
                <box size="0.36658421524776585 0.5241061539914771 1.821255534563132" />
            </geometry>
            <material name="Green">
                <color rgba="0 1 0 1.0"/>
            </material>
        </visual>
        <collision>
            <origin xyz="0 0 0.910627767281566" rpy="0 0 0"/>
            <geometry>
                <box size="0.36658421524776585 0.5241061539914771 1.821255534563132" />
            </geometry>
        </collision>
    </link>
    <joint name="0_1" type="revolute">
       <parent link="0"/>
       <child  link="1"/>
       <origin rpy="0 0 0" xyz="0 0.4487963041817653 0.75" />
     <axis xyz="0 1 0"/>
       <limit effort="0.0" lower="-3.14159" upper="3.14159" velocity="0.0"/>
    </joint>
    <link name="1">
        <inertial>
            <origin xyz="0 0.7232001197988408 0" rpy="0 0 0"/>
            <mass value="1" />
            <inertia ixx="100" ixy="0" ixz="0" iyy="100" iyz="0" izz="100" />
        </inertial>
        <visual>
            <origin xyz="0 0.7232001197988408 0" rpy="0 0 0"/>
            <geometry>
                <box size="0.8845560712453234 1.4464002395976816 1.7891925584141517" />
            </geometry>
            <material name="Blue">
                <color rgba="0 0 1 1.0"/>
            </material>
        </visual>
        <collision>
            <origin xyz="0 0.7232001197988408 0" rpy="0 0 0"/>
            <geometry>
                <box size="0.8845560712453234 1.4464002395976816 1.7891925584141517" />
            </geometry>
        </collision>
    </link>
    <joint name="1_2addl" type="revolute">
       <parent link="1"/>
       <child  link="2addl"/>
       <origin rpy="0 0 0" xyz="0 1.4464002395976816 0" />
     <axis xyz="1 0 0"/>
       <limit effort="0.0" lower="-3.14159" upper="3.14159" velocity="0.0"/>
    </joint>
    <link name="2addl">
        <inertial>
            <origin xyz="0 0.05966736292317391 0" rpy="0 0 0"/>
            <mass value="1" />
            <inertia ixx="100" ixy="0" ixz="0" iyy="100" iyz="0" izz="100" />
        </inertial>
        <visual>
            <origin xyz="0 0.05966736292317391 0" rpy="0 0 0"/>
            <geometry>
                <box size="0.4844915569094088 0.11933472584634781 1.1843269090150657" />
            </geometry>
            <material name="Blue">
                <color rgba="0 0 1 1.0"/>
            </material>
        </visual>
        <collision>
            <origin xyz="0 0.05966736292317391 0" rpy="0 0 0"/>
            <geometry>
                <box size="0.4844915569094088 0.11933472584634781 1.1843269090150657" />
            </geometry>
        </collision>
    </link>
    <joint name="1_2" type="revolute">
       <parent link="1"/>
       <child  link="2"/>
       <origin rpy="0 0 0" xyz="0 0.7232001197988408 0.8945962792070759" />
     <axis xyz="0 0 1"/>
       <limit effort="0.0" lower="-3.14159" upper="3.14159" velocity="0.0"/>
    </joint>
    <link name="2">
        <inertial>
            <origin xyz="0 0 0.37790730454648713" rpy="0 0 0"/>
            <mass value="1" />
            <inertia ixx="100" ixy="0" ixz="0" iyy="100" iyz="0" izz="100" />
        </inertial>
        <visual>
            <origin xyz="0 0 0.37790730454648713" rpy="0 0 0"/>
            <geometry>
                <box size="0.4632849501235576 0.6065871485555316 0.7558146090929743" />
            </geometry>
            <material name="Green">
                <color rgba="0 1 0 1.0"/>
            </material>
        </visual>
        <collision>
            <origin xyz="0 0 0.37790730454648713" rpy="0 0 0"/>
            <geometry>
                <box size="0.4632849501235576 0.6065871485555316 0.7558146090929743" />
            </geometry>
        </collision>
    </link>
    <joint name="2_3" type="revolute">
       <parent link="2"/>
       <child  link="3"/>
       <origin rpy="0 0 0" xyz="0 0 0.7558146090929743" />
     <axis xyz="1 0 0"/>
       <limit effort="0.0" lower="-3.14159" upper="3.14159" velocity="0.0"/>
    </joint>
    <link name="3">
        <inertial>
            <origin xyz="0 0 0.6307347834181997" rpy="0 0 0"/>
            <mass value="1" />
            <inertia ixx="100" ixy="0" ixz="0" iyy="100" iyz="0" izz="100" />
        </inertial>
        <visual>
            <origin xyz="0 0 0.6307347834181997" rpy="0 0 0"/>
            <geometry>
                <box size="1.9539702897465303 1.4746635926903187 1.2614695668363993" />
            </geometry>
            <material name="Green">
                <color rgba="0 1 0 1.0"/>
            </material>
        </visual>
        <collision>
            <origin xyz="0 0 0.6307347834181997" rpy="0 0 0"/>
            <geometry>
                <box size="1.9539702897465303 1.4746635926903187 1.2614695668363993" />
            </geometry>
        </collision>
    </link>
    <joint name="3_4" type="revolute">
       <parent link="3"/>
       <child  link="4"/>
       <origin rpy="0 0 0" xyz="0 0.7373317963451593 0.6307347834181997" />
     <axis xyz="0 1 0"/>
       <limit effort="0.0" lower="-3.14159" upper="3.14159" velocity="0.0"/>
    </joint>
    <link name="4">
        <inertial>
            <origin xyz="0 0.12174145886627423 0" rpy="0 0 0"/>
            <mass value="1" />
            <inertia ixx="100" ixy="0" ixz="0" iyy="100" iyz="0" izz="100" />
        </inertial>
        <visual>
            <origin xyz="0 0.12174145886627423 0" rpy="0 0 0"/>
            <geometry>
                <box size="0.3522867271723636 0.24348291773254846 1.3143007938811087" />
            </geometry>
            <material name="Blue">
                <color rgba="0 0 1 1.0"/>
            </material>
        </visual>
        <collision>
            <origin xyz="0 0.12174145886627423 0" rpy="0 0 0"/>
            <geometry>
                <box size="0.3522867271723636 0.24348291773254846 1.3143007938811087" />
            </geometry>
        </collision>
    </link>
    <joint name="4_5addl" type="revolute">
       <parent link="4"/>
       <child  link="5addl"/>
       <origin rpy="0 0 0" xyz="0 0.12174145886627423 0.6571503969405543" />
     <axis xyz="0 1 0"/>
       <limit effort="0.0" lower="-3.14159" upper="3.14159" velocity="0.0"/>
    </joint>
    <link name="5addl">
        <inertial>
            <origin xyz="0 0 0.7389862937304205" rpy="0 0 0"/>
            <mass value="1" />
            <inertia ixx="100" ixy="0" ixz="0" iyy="100" iyz="0" izz="100" />
        </inertial>
        <visual>
            <origin xyz="0 0 0.7389862937304205" rpy="0 0 0"/>
            <geometry>
                <box size="0.48622150609906506 0.3553222970548465 1.477972587460841" />
            </geometry>
            <material name="Green">
                <color rgba="0 1 0 1.0"/>
            </material>
        </visual>
        <collision>
            <origin xyz="0 0 0.7389862937304205" rpy="0 0 0"/>
            <geometry>
                <box size="0.48622150609906506 0.3553222970548465 1.477972587460841" />
            </geometry>
        </collision>
    </link>
    <joint name="4_5" type="revolute">
       <parent link="4"/>
       <child  link="5"/>
       <origin rpy="0 0 0" xyz="0 0.24348291773254846 0" />
     <axis xyz="0 0 1"/>
       <limit effort="0.0" lower="-3.14159" upper="3.14159" velocity="0.0"/>
    </joint>
    <link name="5">
        <inertial>
            <origin xyz="0 0.8222178394105932 0" rpy="0 0 0"/>
            <mass value="1" />
            <inertia ixx="100" ixy="0" ixz="0" iyy="100" iyz="0" izz="100" />
        </inertial>
        <visual>
            <origin xyz="0 0.8222178394105932 0" rpy="0 0 0"/>
            <geometry>
                <box size="1.0668864731545136 1.6444356788211865 1.2486064698183554" />
            </geometry>
            <material name="Blue">
                <color rgba="0 0 1 1.0"/>
            </material>
        </visual>
        <collision>
            <origin xyz="0 0.8222178394105932 0" rpy="0 0 0"/>
            <geometry>
                <box size="1.0668864731545136 1.6444356788211865 1.2486064698183554" />
            </geometry>
        </collision>
    </link>
</robot>