<robot name = "robot">
    <link name="0">
        <inertial>
            <origin xyz="0 0 0.75" rpy="0 0 0"/>
            <mass value="1" />
            <inertia ixx="100" ixy="0" ixz="0" iyy="100" iyz="0" izz="100" />
        </inertial>
        <visual>
            <origin xyz="0 0 0.75" rpy="0 0 0"/>
            <geometry>
                <box size="0.867986890667591 1.4482528797263223 1.4700004511837204" />
            </geometry>
            <material name="Blue">
                <color rgba="0 0 1 1.0"/>
            </material>
        </visual>
        <collision>
            <origin xyz="0 0 0.75" rpy="0 0 0"/>
            <geometry>
                <box size="0.867986890667591 1.4482528797263223 1.4700004511837204" />
            </geometry>
        </collision>
    </link>
    <joint name="0_1" type="revolute">
       <parent link="0"/>
       <child  link="1"/>
       <origin rpy="0 0 0" xyz="0.4339934453337955 0 0.75" />
     <axis xyz="1 0 0"/>
       <limit effort="0.0" lower="-3.14159" upper="3.14159" velocity="0.0"/>
    </joint>
    <link name="1">
        <inertial>
            <origin xyz="1.0499210073387555 0 0" rpy="0 0 0"/>
            <mass value="1" />
            <inertia ixx="100" ixy="0" ixz="0" iyy="100" iyz="0" izz="100" />
        </inertial>
        <visual>
            <origin xyz="1.0499210073387555 0 0" rpy="0 0 0"/>
            <geometry>
                <box size="2.099842014677511 0.5426479921098792 0.3989345268905745" />
            </geometry>
            <material name="Blue">
                <color rgba="0 0 1 1.0"/>
            </material>
        </visual>
        <collision>
            <origin xyz="1.0499210073387555 0 0" rpy="0 0 0"/>
            <geometry>
                <box size="2.099842014677511 0.5426479921098792 0.3989345268905745" />
            </geometry>
        </collision>
    </link>
    <joint name="1_2" type="revolute">
       <parent link="1"/>
       <child  link="2"/>
       <origin rpy="0 0 0" xyz="1.0499210073387555 0 0.19946726344528726" />
     <axis xyz="1 0 0"/>
       <limit effort="0.0" lower="-3.14159" upper="3.14159" velocity="0.0"/>
    </joint>
    <link name="2">
        <inertial>
            <origin xyz="0 0 0.37792292552527296" rpy="0 0 0"/>
            <mass value="1" />
            <inertia ixx="100" ixy="0" ixz="0" iyy="100" iyz="0" izz="100" />
        </inertial>
        <visual>
            <origin xyz="0 0 0.37792292552527296" rpy="0 0 0"/>
            <geometry>
                <box size="0.36664390240956424 0.9517034955991177 0.7558458510505459" />
            </geometry>
            <material name="Green">
                <color rgba="0 1 0 1.0"/>
            </material>
        </visual>
        <collision>
            <origin xyz="0 0 0.37792292552527296" rpy="0 0 0"/>
            <geometry>
                <box size="0.36664390240956424 0.9517034955991177 0.7558458510505459" />
            </geometry>
        </collision>
    </link>
    <joint name="2_3" type="revolute">
       <parent link="2"/>
       <child  link="3"/>
       <origin rpy="0 0 0" xyz="0 0 0.7558458510505459" />
     <axis xyz="0 1 0"/>
       <limit effort="0.0" lower="-3.14159" upper="3.14159" velocity="0.0"/>
    </joint>
    <link name="3">
        <inertial>
            <origin xyz="0 0 0.6553746482632662" rpy="0 0 0"/>
            <mass value="1" />
            <inertia ixx="100" ixy="0" ixz="0" iyy="100" iyz="0" izz="100" />
        </inertial>
        <visual>
            <origin xyz="0 0 0.6553746482632662" rpy="0 0 0"/>
            <geometry>
                <box size="0.24025296468919263 1.2955133534362735 1.3107492965265324" />
            </geometry>
            <material name="Blue">
                <color rgba="0 0 1 1.0"/>
            </material>
        </visual>
        <collision>
            <origin xyz="0 0 0.6553746482632662" rpy="0 0 0"/>
            <geometry>
                <box size="0.24025296468919263 1.2955133534362735 1.3107492965265324" />
            </geometry>
        </collision>
    </link>
    <joint name="3_4" type="revolute">
       <parent link="3"/>
       <child  link="4"/>
       <origin rpy="0 0 0" xyz="0 0.6477566767181367 0.6553746482632662" />
     <axis xyz="1 0 0"/>
       <limit effort="0.0" lower="-3.14159" upper="3.14159" velocity="0.0"/>
    </joint>
    <link name="4">
        <inertial>
            <origin xyz="0 0.26209115837442765 0" rpy="0 0 0"/>
            <mass value="1" />
            <inertia ixx="100" ixy="0" ixz="0" iyy="100" iyz="0" izz="100" />
        </inertial>
        <visual>
            <origin xyz="0 0.26209115837442765 0" rpy="0 0 0"/>
            <geometry>
                <box size="1.2197543793117862 0.5241823167488553 0.45908427973679267" />
            </geometry>
            <material name="Green">
                <color rgba="0 1 0 1.0"/>
            </material>
        </visual>
        <collision>
            <origin xyz="0 0.26209115837442765 0" rpy="0 0 0"/>
            <geometry>
                <box size="1.2197543793117862 0.5241823167488553 0.45908427973679267" />
            </geometry>
        </collision>
    </link>
</robot>