<robot name = "robot">
    <link name="0">
        <inertial>
            <origin xyz="0 0 0.75" rpy="0 0 0"/>
            <mass value="1" />
            <inertia ixx="100" ixy="0" ixz="0" iyy="100" iyz="0" izz="100" />
        </inertial>
        <visual>
            <origin xyz="0 0 0.75" rpy="0 0 0"/>
            <geometry>
                <box size="0.6133797084656504 0.3338588483480708 1.1807130717628438" />
            </geometry>
            <material name="Green">
                <color rgba="0 1 0 1.0"/>
            </material>
        </visual>
        <collision>
            <origin xyz="0 0 0.75" rpy="0 0 0"/>
            <geometry>
                <box size="0.6133797084656504 0.3338588483480708 1.1807130717628438" />
            </geometry>
        </collision>
    </link>
    <joint name="0_1addl" type="revolute">
       <parent link="0"/>
       <child  link="1addl"/>
       <origin rpy="0 0 0" xyz="0.3066898542328252 0 0.75" />
     <axis xyz="0 1 0"/>
       <limit effort="0.0" lower="-3.14159" upper="3.14159" velocity="0.0"/>
    </joint>
    <link name="1addl">
        <inertial>
            <origin xyz="0.3588193621217528 0 0" rpy="0 0 0"/>
            <mass value="1" />
            <inertia ixx="100" ixy="0" ixz="0" iyy="100" iyz="0" izz="100" />
        </inertial>
        <visual>
            <origin xyz="0.3588193621217528 0 0" rpy="0 0 0"/>
            <geometry>
                <box size="0.7176387242435056 0.2777812716774791 0.1144900753706827" />
            </geometry>
            <material name="Blue">
                <color rgba="0 0 1 1.0"/>
            </material>
        </visual>
        <collision>
            <origin xyz="0.3588193621217528 0 0" rpy="0 0 0"/>
            <geometry>
                <box size="0.7176387242435056 0.2777812716774791 0.1144900753706827" />
            </geometry>
        </collision>
    </link>
    <joint name="0_1" type="revolute">
       <parent link="0"/>
       <child  link="1"/>
       <origin rpy="0 0 0" xyz="0 0 1.3403565358814218" />
     <axis xyz="0 0 1"/>
       <limit effort="0.0" lower="-3.14159" upper="3.14159" velocity="0.0"/>
    </joint>
    <link name="1">
        <inertial>
            <origin xyz="0 0 1.1358222285259998" rpy="0 0 0"/>
            <mass value="1" />
            <inertia ixx="100" ixy="0" ixz="0" iyy="100" iyz="0" izz="100" />
        </inertial>
        <visual>
            <origin xyz="0 0 1.1358222285259998" rpy="0 0 0"/>
            <geometry>
                <box size="1.2285100186999345 1.2456661206555224 2.2716444570519996" />
            </geometry>
            <material name="Blue">
                <color rgba="0 0 1 1.0"/>
            </material>
        </visual>
        <collision>
            <origin xyz="0 0 1.1358222285259998" rpy="0 0 0"/>
            <geometry>
                <box size="1.2285100186999345 1.2456661206555224 2.2716444570519996" />
            </geometry>
        </collision>
    </link>
    <joint name="1_2addl" type="revolute">
       <parent link="1"/>
       <child  link="2addl"/>
       <origin rpy="0 0 0" xyz="0 0 2.2716444570519996" />
     <axis xyz="1 0 0"/>
       <limit effort="0.0" lower="-3.14159" upper="3.14159" velocity="0.0"/>
    </joint>
    <link name="2addl">
        <inertial>
            <origin xyz="0 0 0.19835308170965862" rpy="0 0 0"/>
            <mass value="1" />
            <inertia ixx="100" ixy="0" ixz="0" iyy="100" iyz="0" izz="100" />
        </inertial>
        <visual>
            <origin xyz="0 0 0.19835308170965862" rpy="0 0 0"/>
            <geometry>
                <box size="0.21023116149811874 0.21342291336536398 0.39670616341931725" />
            </geometry>
            <material name="Blue">
                <color rgba="0 0 1 1.0"/>
            </material>
        </visual>
        <collision>
            <origin xyz="0 0 0.19835308170965862" rpy="0 0 0"/>
            <geometry>
                <box size="0.21023116149811874 0.21342291336536398 0.39670616341931725" />
            </geometry>
        </collision>
    </link>
    <joint name="1_2" type="revolute">
       <parent link="1"/>
       <child  link="2"/>
       <origin rpy="0 0 0" xyz="0 0.6228330603277612 1.1358222285259998" />
     <axis xyz="0 0 1"/>
       <limit effort="0.0" lower="-3.14159" upper="3.14159" velocity="0.0"/>
    </joint>
    <link name="2">
        <inertial>
            <origin xyz="0 1.4118296817867393 0" rpy="0 0 0"/>
            <mass value="1" />
            <inertia ixx="100" ixy="0" ixz="0" iyy="100" iyz="0" izz="100" />
        </inertial>
        <visual>
            <origin xyz="0 1.4118296817867393 0" rpy="0 0 0"/>
            <geometry>
                <box size="0.7261187488734128 2.8236593635734786 1.4832532814840043" />
            </geometry>
            <material name="Green">
                <color rgba="0 1 0 1.0"/>
            </material>
        </visual>
        <collision>
            <origin xyz="0 1.4118296817867393 0" rpy="0 0 0"/>
            <geometry>
                <box size="0.7261187488734128 2.8236593635734786 1.4832532814840043" />
            </geometry>
        </collision>
    </link>
</robot>