<robot name = "robot">
    <link name="0">
        <inertial>
            <origin xyz="0 0 0.75" rpy="0 0 0"/>
            <mass value="1" />
            <inertia ixx="100" ixy="0" ixz="0" iyy="100" iyz="0" izz="100" />
        </inertial>
        <visual>
            <origin xyz="0 0 0.75" rpy="0 0 0"/>
            <geometry>
                <box size="1.28400327677293 0.3740374958462731 0.6179611141237232" />
            </geometry>
            <material name="Green">
                <color rgba="0 1 0 1.0"/>
            </material>
        </visual>
        <collision>
            <origin xyz="0 0 0.75" rpy="0 0 0"/>
            <geometry>
                <box size="1.28400327677293 0.3740374958462731 0.6179611141237232" />
            </geometry>
        </collision>
    </link>
    <joint name="0_1addl" type="revolute">
       <parent link="0"/>
       <child  link="1addl"/>
       <origin rpy="0 0 0" xyz="0 0 1.0589805570618616" />
     <axis xyz="1 0 0"/>
       <limit effort="0.0" lower="-3.14159" upper="3.14159" velocity="0.0"/>
    </joint>
    <link name="1addl">
        <inertial>
            <origin xyz="0 0 0.3137507468308496" rpy="0 0 0"/>
            <mass value="1" />
            <inertia ixx="100" ixy="0" ixz="0" iyy="100" iyz="0" izz="100" />
        </inertial>
        <visual>
            <origin xyz="0 0 0.3137507468308496" rpy="0 0 0"/>
            <geometry>
                <box size="0.40246855909054247 0.28109156814624514 0.6275014936616992" />
            </geometry>
            <material name="Green">
                <color rgba="0 1 0 1.0"/>
            </material>
        </visual>
        <collision>
            <origin xyz="0 0 0.3137507468308496" rpy="0 0 0"/>
            <geometry>
                <box size="0.40246855909054247 0.28109156814624514 0.6275014936616992" />
            </geometry>
        </collision>
    </link>
    <joint name="0_1" type="revolute">
       <parent link="0"/>
       <child  link="1"/>
       <origin rpy="0 0 0" xyz="0.642001638386465 0 0.75" />
     <axis xyz="0 0 1"/>
       <limit effort="0.0" lower="-3.14159" upper="3.14159" velocity="0.0"/>
    </joint>
    <link name="1">
        <inertial>
            <origin xyz="1.27969276224489 0 0" rpy="0 0 0"/>
            <mass value="1" />
            <inertia ixx="100" ixy="0" ixz="0" iyy="100" iyz="0" izz="100" />
        </inertial>
        <visual>
            <origin xyz="1.27969276224489 0 0" rpy="0 0 0"/>
            <geometry>
                <box size="2.55938552448978 1.0580745975160586 1.410468575111678" />
            </geometry>
            <material name="Green">
                <color rgba="0 1 0 1.0"/>
            </material>
        </visual>
        <collision>
            <origin xyz="1.27969276224489 0 0" rpy="0 0 0"/>
            <geometry>
                <box size="2.55938552448978 1.0580745975160586 1.410468575111678" />
            </geometry>
        </collision>
    </link>
    <joint name="1_2" type="revolute">
       <parent link="1"/>
       <child  link="2"/>
       <origin rpy="0 0 0" xyz="1.27969276224489 0 0.705234287555839" />
     <axis xyz="1 0 0"/>
       <limit effort="0.0" lower="-3.14159" upper="3.14159" velocity="0.0"/>
    </joint>
    <link name="2">
        <inertial>
            <origin xyz="0 0 1.1263805390370345" rpy="0 0 0"/>
            <mass value="1" />
            <inertia ixx="100" ixy="0" ixz="0" iyy="100" iyz="0" izz="100" />
        </inertial>
        <visual>
            <origin xyz="0 0 1.1263805390370345" rpy="0 0 0"/>
            <geometry>
                <box size="0.47638396046181175 0.19607835782720565 2.252761078074069" />
            </geometry>
            <material name="Green">
                <color rgba="0 1 0 1.0"/>
            </material>
        </visual>
        <collision>
            <origin xyz="0 0 1.1263805390370345" rpy="0 0 0"/>
            <geometry>
                <box size="0.47638396046181175 0.19607835782720565 2.252761078074069" />
            </geometry>
        </collision>
    </link>
</robot>